Workbook

Sheet Libro de reservas
F1: Noviembre | V1: 46357 | AX1: 46388 | CC1: 46419 | DE1: 46447 | EJ1: 46478
J3: D | Q3: D | X3: D | AE3: D | AL3: D | AS3: D | AZ3: D | BG3: D | BN3: D | BU3: DD | CB3: D | CI3: D | CP3: D | CW3: D | DD3: D | DK3: D | DR3: D | DY3: D | EF3: D | EM3: D | ET3: D | FA3: D | FH3: D
H4: FINDE LARGO | V4: FINDE LARGO | CG4: FINDE LARGO CARNAVAL
D5: 46342 | E5: 46343 | F5: 46344 | G5: 46345 | H5: 46346 | I5: 45982 | J5: 45983 | K5: 45984 | L5: 45985 | M5: 45986 | N5: 45987 | O5: 45988 | P5: 45989 | Q5: 45990 | R5: 45991 | S5: 45992 | T5: 45993 | U5: 44533 | V5: 44169 | W5: 44170 | X5: 44171 | Y5: 44172 | Z5: 44173 | AA5: 44174 | AB5: 44175 | AC5: 44176 | AD5: 44177 | AE5: 44178 | AF5: 44179 | AG5: 44180 | AH5: 44181 | AI5: 44182 | AJ5: 44548 | AK5: 44184 | AL5: 44185 | AM5: 44186 | AN5: 44187 | AO5: 44188 | AP5: 44189 | AQ5: 44190 | AR5: 44191 | AS5: 44192 | AT5: 44193 | AU5: 44194 | AV5: 44195 | AW5: 44196 | AX5: 43831 | AY5: 43832 | AZ5: 43833 | BA5: 43834 | BB5: 43835 | BC5: 43836 | BD5: 43837 | BE5: 43838 | BF5: 43839 | BG5: 43840 | BH5: 43841 | BI5: 43842 | BJ5: 43843 | BK5: 43844 | BL5: 43845 | BM5: 43846 | BN5: 43847 | BO5: 43848 | BP5: 43849 | BQ5: 43850 | BR5: 43851 | BS5: 43852 | BT5: 43853 | BU5: 43854 | BV5: 43855 | BW5: 43856 | BX5: 43857 | BY5: 43858 | BZ5: 43859 | CA5: 43860 | CB5: 43861 | CC5: 43862 | CD5: 43863 | CE5: 43864 | CF5: 43865 | CG5: 43866 | CH5: 43867 | CI5: 43868 | CJ5: 43869 | CK5: 43870 | CL5: 43871 | CM5: 43872 | CN5: 43873 | CO5: 43874 | CP5: 43875 | CQ5: 43876 | CR5: 43877 | CS5: 43878 | CT5: 43879 | CU5: 43880 | CV5: 43881 | CW5: 43882 | CX5: 43883 | CY5: 43884 | CZ5: 43885 | DA5: 43886 | DB5: 43887 | DC5: 43888 | DD5: 43889 | DE5: 43891 | DF5: 43892 | DG5: 43893 | DH5: 43894 | DI5: 43895 | DJ5: 43896 | DK5: 44262 | DL5: 44263 | DM5: 44264 | DN5: 44265 | DO5: 44266 | DP5: 44267 | DQ5: 44268 | DR5: 44269 | DS5: 44270 | DT5: 44271 | DU5: 44272 | DV5: 44273 | DW5: 44274 | DX5: 44275 | DY5: 44276 | DZ5: 44277 | EA5: 44278 | EB5: 44279 | EC5: 44280 | ED5: 44281 | EE5: 44282 | EF5: 44283 | EG5: 44284 | EH5: 44285 | EI5: 44286 | EJ5: 44287 | EK5: 44288 | EL5: 44289 | EM5: 44290 | EN5: 44291 | EO5: 44292 | EP5: 44293 | EQ5: 44294 | ER5: 44295 | ES5: 44296 | ET5: 44297 | EU5: 44298 | EV5: 44299 | EW5: 44300 | EX5: 44301 | EY5: 44302 | EZ5: 44303 | FA5: 44304 | FB5: 44305 | FC5: 44306 | FD5: 44307 | FE5: 44308 | FF5: 44309 | FG5: 44310 | FH5: 44311 | FI5: 44312 | FJ5: 44313 | FK5: 44314 | FL5: 44315 | FM5: 44316
A6: 1 | B6: H3 | AS6: SC Laura Spinelli x 3 + bebe - no mover
A7: 2 | B7: H2 | AV7: Nidia Marini x 1 - Planta baja
A8: 3 | B8: H3 | AY8: Julio Cassanello x 2 planta baja | BF8: José Podestá - x 2 - no mover
A9: 5 | B9: D4 | AT9: Belen Albar Diaz - x 4 - no mover
A10: 6 | B10: D4 | AS10: Osvaldo Cordero x 4 no mover
A11: 7 | B11: H2 | AS11: Nelida Torrillo x 2 P. baja | BB11: Jorge Cozzi x 2 - no mover | CC11: Neli Senga x 2 camas p. baja
A12: 8 | B12: H2 | AO12: Marchese x4 | AV12: Johanna Bauer x 4 - 1° piso y 2 baños | CC12: BK Silvia Paiges - x 4 camas
A13: 9 | B13: H2
A14: 10 | B14: H2 | BE14: Cozzi x 2 camas
A15: 11 | B15: H3
A16: 12 | B16: H3 | CQ16: Juan Carlos Arce - x 2 - no mover
A17: 13 | B17: H3
A18: 14 | B18: H3
A19: 15 | B19: H3
A20: 16 | B20: H2 | AV20: SC Drago/Farinelli x 2
A21: 17 | B21: D3 | AO21: Marchese x3 | BE21: Jorge Cozzi x 3 | CC21: SC Silvina Molina x 3 camas - no mover - sale x la tarde
A22: 18 | B22: D4 | AO22: Marchese x4 | BA22: SC x 4 -> | CC22: Vanina Corrado x 4
A23: 19 | B23: H2 | AV23: Edward Hansen x 2 * | BA23: SC Ángeles de la Vega x 1 -> | BG23: SC De la Vega x 2 -> | CN23: Sc Raúl Rossini x 1 - no mover
A24: 21 | B24: H2 | AO24: Marchese x2 | AU24: Irma Teresa Maio - x 2 camas | BE24: Cozzi x 2 mat | CA24: Romina Fabbio x 2 camas
A25: 22 | B25: H3 | AV25: BK Daniel Bonanno - 2 camas c/balcón | BH25: BK Ana Luz La banca - x 2 mat
A26: 23 | B26: H2
A27: 24 | B27: H2 | AR27: Jorge Aguirre x 2 - con balcón | AY27: Claudia Cabrera x 2 - con balcón | BK27: SC <- De la Vega x 2 no mover | BP27: Laura Pereyra x 2 - con balcón | CW27: Carmen y Carlos Segreti x 2 mat con balcón
A28: 25 | B28: H2 | AO28: Marchese x1 | BA28: Patricia Gauna x 1 | CN28: Pedro Marchese x 1 - poner tacos en respaldo de sommier
A29: 26 | B29: H2 | AU29: SC Carlos Magno - x 2 - con balcón
A30: 27 | B30: H2 | AY30: Irma Udrizard x 1 | BF30: Cecilia Podesta -x 1 no mover
A31: 28 | B31: H3 | AP31: Jorge Aguirre x 2 - | AY31: Liliana Traficante - x 2 no mover | CG31: Oscar Gonzalez x 3
A32: 29 | B32: H2 | AN32: SC Lipschitz x 2 - no mover | CF32: Norma Murcian x 2 camas - con balcón | CQ32: Marcela Bianchi x 2 camas con balcón
A33: 30 | B33: H2 | BB33: Romina Rozas x 2 camas
A34: 31 | B34: H1 | AR34: Teresa Mauri - x 1 - sólo desayuno - no mover | BN34: Sc Fatima de Paula x 1 | DA34: Ernesto Catani x 1 no mover
A35: 32 | B35: H1 | AI35: Bonilauri x 1 | BA35: Sc Eleonora Falcón x 1 - no mover
A36: 33 | B36: H3 | AZ36: Graciela Herrera - x 2 no mover | BT36: Alejandro Canals x 3 + cuna chica
A37: 34 | B37: H2 | BT37: Alejandro Canals x 2
A38: 35 | B38: H3 | AU38: SC Alberto Garcia - x 4 - dos mat | BC38: SC -> Lipschitz x 4 - no mover
A39: 36 | B39: H2
A40: via I | AU40: SC Verdino | AX40: SC Valeria Verdino x 2 | CC40: SC Hermano Sotelo Valenzuela x 4
A41: Tilo | AX41: Dante Mereles x 5 | CC41: Mariana Valenzuela x 4
...

Sheet  Reservas
A1: ID Reserva | B1: Habitación | C1: Nombre | D1: Apellido | E1: Check-in | F1: Check-out | G1: Cantidad de personas | H1: Plan | I1: Estado | J1: Observaciones
A2: #00001 | B2: El Tilo | C2: Mariana | D2: Sotelo Valenzuela | E2: 46419 | F2: 46426 | G2: 4 | H2: Sin desayuno | I2: Con Seña | J2: Link de pago - Visa
A3: #00002 | B3: 24 | C3: Laura | D3: Pereyra | E3: 46406 | F3: 46415 | G3: 2 | H3: Media pensión | I3: Pago Total | J3: Con balcón
A4: #00003 | B4: 24 | C4: Claudia | D4: Cabrera | E4: 46389 | F4: 46401 | G4: 2 | H4: Media pensión | I4: Con Seña | J4: Con balcón
A5: #00004 | B5: 31 | C5: Teresa | D5: Macchiavello | E5: 46382 | F5: 46399 | G5: 1 | H5: Con desayuno | I5: Con Seña | J5: Con balcón - no mover
A6: #00005 | B6: 3 | C6: Jose | D6: Podesta | E6: 46396 | F6: 46405 | G6: 2 | H6: Media pensión | I6: Con Seña | J6: No mover
A7: #00006 | B7: 33 | C7: Alejandro | D7: Canals | E7: 46410 | F7: 46415 | G7: 3 + bebe | H7: Media pensión | I7: Con Seña
A8: #00007 | B8: 34 | C8: Alejandro | D8: Canals | E8: 46410 | F8: 46415 | G8: 2 | H8: Media pensión | I8: Con Seña
A9: #00008 | B9: 33 | C9: Graciela | D9: Herrera | E9: 46390 | F9: 46404 | G9: 2 | H9: Media pensión | I9: Sin seña | J9: Abona en USD - no mover
A10: #00009 | B10: 24 | C10: Carmen | D10: Segreti | E10: 46439 | F10: 46447 | G10: 2 | H10: Media pensión | I10: Con Seña | J10: Con balcón
A11: #00010 | B11: 3 | C11: Julio | D11: Cassanello | E11: 46389 | F11: 46396 | G11: 2 | H11: Media pensión | I11: Con Seña | J11: Planta baja
A12: #00011 | B12: 28 | C12: Oscar | D12: Gonzalez | E12: 46423 | F12: 46428 | G12: 3 | H12: Media pensión | I12: Con Seña
A13: #00012 | B13: 2 | C13: Nidia | D13: Marini | E13: 46386 | F13: 46398 | G13: 1 | H13: Media pensión | I13: Con Seña | J13: Planta baja
A14: #00013 | B14: 8 y 9 | C14: Johanna | D14: Bauer | E14: 46386 | F14: 46398 | G14: 4 | H14: Media pensión | I14: Con Seña | J14: 1° piso, dos baños
A15: #00014 | B15: 25 | C15: Patricia | D15: Gauna | E15: 46391 | F15: 46398 | G15: 1 | H15: Media pensión | I15: Con Seña
A16: #00015 | B16: Esquinita | C16: Analia | D16: Grosso | E16: 46410 | F16: 46419 | G16: 4 | H16: Sin desayuno | I16: Con Seña | J16: Pasa a vía de quedar libre - NO
A17: #00016 | B17: 29 | C17: Norma | D17: Murcian | E17: 46422 | F17: 46432 | G17: 2 | H17: Media pensión | I17: Con Seña | J17: Con balcón - dos camas
A18: #00017 | B18: 25 | C18: Pedro | D18: Marchese | E18: 46379 | F18: 46382 | G18: 1 | H18: Media pensión | I18: Con Seña | J18: Poner tacos en respaldo
A19: #00018 | B19: 21 | C19: Pedro | D19: Marchese | E19: 46382 | F19: 46382 | G19: 2 | H19: Media pensión | I19: Con Seña
A20: #00019 | B20: 17 | C20: Pedro | D20: Marchese | E20: 46382 | F20: 46382 | G20: 3 | H20: Media pensión | I20: Con Seña
A21: #00020 | B21: 18 | C21: Pedro | D21: Marchese | E21: 46379 | F21: 46382 | G21: 4 | H21: Media pensión | I21: Con Seña
A22: #00021 | B22: 8 y 9 | C22: Pedro | D22: Marchese | E22: 46379 | F22: 46382 | G22: 4 | H22: Media pensión | I22: Con Seña
A23: #00022 | B23: 27 | C23: Cecilia | D23: Podesta | E23: 46396 | F23: 46405 | G23: 1 | H23: Media pensión | I23: Con Seña | J23: No mover
A24: #00023 | B24: 6 | C24: Osvaldo | D24: Cordero | E24: 46383 | F24: 46388 | G24: 4 | H24: Media pensión | I24: Con Seña | J24: No mover
A25: #00024 | B25: 1 | C25: Laura | D25: Spinelli | E25: 46383 | F25: 46397 | G25: 3 + bb | H25: Media pensión | J25: No mover
A26: #00025 | B26: 35 y 36 | C26: Alberto | D26: Garcia | E26: 46385 | F26: 46393 | G26: 4 | H26: Media pensión | J26: No mover
A27: #00026 | B27: 19 | C27: Raúl | D27: Rossini | E27: 46430 | F27: 46443 | G27: 1 | H27: Media pensión | J27: No mover
A28: #00027 | B28: 28 | C28: Liliana | D28: Traficante | E28: 46389 | F28: 46396 | G28: 2 | H28: Media pensión | I28: Con Seña | J28: No mover
A29: #00028 | B29: 27 | C29: Irma | D29: Udrizard | E29: 46389 | F29: 46396 | G29: 1 | H29: Media pensión | I29: Con Seña
A30: #00029 | B30: 22 | C30: Ana Luz | D30: La Banca | E30: 46398 | F30: 46405 | G30: 2 | H30: Media pensión | J30: Booking
A31: #00030 | B31: 05 | C31: Belen | D31: Albar Diaz | E31: 46384 | F31: 46397 | G31: 4 | H31: Media pensión | I31: Con Seña | J31: No mover
A32: #00031 | B32: 30 | C32: Romina | D32: Rozas | E32: 46392 | F32: 46397 | G32: 2 | H32: Media pensión | I32: Con Seña | J32: 2 camas
A33: #00032 | B33: 21 | C33: Irma | D33: Maio | E33: 46385 | F33: 46395 | G33: 2 | H33: Media pensión | I33: Con Seña | J33: 2 camas
A34: #00033 | B34: 22 | C34: Daniel | D34: Bonanno | E34: 46386 | F34: 46393 | G34: 2 | H34: Media pensión | J34: Booking
A35: #00034 | B35: 7 | C35: Nelina | D35: Torrillo | E35: 46383 | F35: 46388 | G35: 2 | H35: Media pensión | I35: Con Seña | J35: Planta baja
A36: #00035 | B36: Esquinita | C36: Anabella | D36: Tiberi | E36: 46389 | F36: 46396 | G36: 4 | H36: Sin desayuno | I36: Con Seña
A37: #00036 | B37: 7 | C37: Neli | D37: Senga | E37: 46419 | F37: 46424 | G37: 2 | H37: Media pensión | I37: Con Seña | J37: Dos camas - Planta baja
A38: #00037 | B38: Esquinita | C38: Andrés | D38: Sotelo Valenzuela | E38: 46419 | F38: 46426 | G38: 4 | H38: Sin desayuno | I38: Con Seña
A39: #00038 | B39: 31 | C39: Ernesto | D39: Catani | E39: 46443 | F39: 46083 | G39: 1 | H39: Media pensión | I39: Con Seña | J39: con balcón
A40: #00039 | B40: 16 | C40: Claudio/Matilde | D40: Drago/Farinelli | E40: 46386 | F40: 46391 | G40: 2 | H40: Media pensión
...

Sheet  Consulta
A1: Fecha a consultar: | B1: 46082
A3: Personas que desayunan | B3: =SUMIFS( Reservas!G:G, Reservas!E:E,"<="&B1-1, Reservas!F:F,">"&B1-1, Reservas!H:H,"<>Sin desayuno" ) -> #N/A
A4: Personas que cenan | B4: =SUMIFS( Reservas!G:G, Reservas!E:E,"<="&B1, Reservas!F:F,">"&B1, Reservas!H:H,"Media pensión" ) -> #N/A | K4: Ingresos | Q4: Egresos
A5: Personas alojadas | B5: =SUMIFS(Reservas!G:G,Reservas!E:E,"<="&B1,Reservas!F:F,">"&B1) -> #N/A | K5: Habitación | L5: Nombre | M5: Apellido | N5: Personas | O5: Plan | Q5: Habitación | R5: Nombre | S5: Apellido | T5: Personas | U5: Plan
A6: Capacidad total de personas | B6: =SUMIF(Habitaciones!C:C,"SI",Habitaciones!B:B) -> #N/A | K6: =IFERROR(__xludf.DUMMYFUNCTION("IFERROR( FILTER( {Reservas!B:B,Reservas!C:C,Reservas!D:D,Reservas!G:G,Reservas!H:H}, INT(Reservas!E:E)=INT(B1) ), ""Sin ingresos hoy"" )"),"Sin ingresos hoy") -> Sin ingresos hoy | Q6: =IFERROR(__xludf.DUMMYFUNCTION("IFERROR( FILTER( {Reservas!B:B,Reservas!C:C,Reservas!D:D,Reservas!G:G,Reservas!H:H}, INT(Reservas!F:F)=INT(B1) ), ""Sin egresos hoy"" )"),"Sin egresos hoy") -> Sin egresos hoy
A7: % de ocupación de personas | B7: =B5/B6 -> #N/A
A8: Total habitaciones | B8: =COUNTIF(Habitaciones!C:C,"SI") -> #REF!
A9: Habitaciones ocupadas | B9: =COUNTIFS(Reservas!E:E,"<="&B1,Reservas!F:F,">"&B1) -> 0
A10: % de ocupación de habitaciones | B10: =B9/B8 -> #REF! | D10: Estado de habitaciones
D11: Habitación | E11: Estado | F11: Personas | G11: Check-in | H11: Check-out | I11: Huésped
D12: =IFERROR(__xludf.DUMMYFUNCTION("filter(Habitaciones!A:A,Habitaciones!C:C=""SI"")"),"#REF!") -> #REF! | E12: =IFERROR(__xludf.DUMMYFUNCTION("IF( IFERROR( ROWS( FILTER( Reservas!B:B, TO_TEXT(TRIM(Reservas!B:B)) = TO_TEXT(TRIM(D12)), Reservas!E:E <= $B$1, Reservas!F:F > $B$1 ) ),0 )>0, ""OCUPADA"", ""LIBRE"" )"),"LIBRE") -> LIBRE | F12: =IFERROR(__xludf.DUMMYFUNCTION("IFERROR( INDEX( FILTER( Reservas!G:G, TRIM(TO_TEXT(Reservas!B:B))=TRIM(TO_TEXT(D12)), Reservas!E:E<=$B$1, Reservas!F:F>$B$1 ), 1 ), """")"),"") | G12: =IFERROR(__xludf.DUMMYFUNCTION("IFERROR( INDEX( FILTER( Reservas!E:E, TRIM(TO_TEXT(Reservas!B:B))=TRIM(TO_TEXT(D12)), Reservas!E:E<=$B$1, Reservas!F:F>$B$1 ), 1 ), """")"),"") | H12: =IFERROR(__xludf.DUMMYFUNCTION("IFERROR( INDEX( FILTER( Reservas!F:F, TRIM(TO_TEXT(Reservas!B:B))=TRIM(TO_TEXT(D12)), Reservas!E:E<=$B$1, Reservas!F:F>$B$1 ), 1 ), """")"),"") | I12: =IFERROR(__xludf.DUMMYFUNCTION("IFERROR( INDEX( FILTER( Reservas!C:C&"" ""&Reservas!D:D, TRIM(TO_TEXT(Reservas!B:B))=TRIM(TO_TEXT(D12)), Reservas!E:E<=$B$1, Reservas!F:F>$B$1 ), 1 ), """")"),"")
E13: =IFERROR(__xludf.DUMMYFUNCTION("IF( IFERROR( ROWS( FILTER( Reservas!B:B, TO_TEXT(TRIM(Reservas!B:B)) = TO_TEXT(TRIM(D13)), Reservas!E:E <= $B$1, Reservas!F:F > $B$1 ) ),0 )>0, ""OCUPADA"", ""LIBRE"" )"),"LIBRE") -> LIBRE | F13: =IFERROR(__xludf.DUMMYFUNCTION("IFERROR( INDEX( FILTER( Reservas!G:G, TRIM(TO_TEXT(Reservas!B:B))=TRIM(TO_TEXT(D13)), Reservas!E:E<=$B$1, Reservas!F:F>$B$1 ), 1 ), """")"),"") | G13: =IFERROR(__xludf.DUMMYFUNCTION("IFERROR( INDEX( FILTER( Reservas!E:E, TRIM(TO_TEXT(Reservas!B:B))=TRIM(TO_TEXT(D13)), Reservas!E:E<=$B$1, Reservas!F:F>$B$1 ), 1 ), """")"),"") | H13: =IFERROR(__xludf.DUMMYFUNCTION("IFERROR( INDEX( FILTER( Reservas!F:F, TRIM(TO_TEXT(Reservas!B:B))=TRIM(TO_TEXT(D13)), Reservas!E:E<=$B$1, Reservas!F:F>$B$1 ), 1 ), """")"),"") | I13: =IFERROR(__xludf.DUMMYFUNCTION("IFERROR( INDEX( FILTER( Reservas!C:C&"" ""&Reservas!D:D, TRIM(TO_TEXT(Reservas!B:B))=TRIM(TO_TEXT(D13)), Reservas!E:E<=$B$1, Reservas!F:F>$B$1 ), 1 ), """")"),"")
E14: =IFERROR(__xludf.DUMMYFUNCTION("IF( IFERROR( ROWS( FILTER( Reservas!B:B, TO_TEXT(TRIM(Reservas!B:B)) = TO_TEXT(TRIM(D14)), Reservas!E:E <= $B$1, Reservas!F:F > $B$1 ) ),0 )>0, ""OCUPADA"", ""LIBRE"" )"),"LIBRE") -> LIBRE | F14: =IFERROR(__xludf.DUMMYFUNCTION("IFERROR( INDEX( FILTER( Reservas!G:G, TRIM(TO_TEXT(Reservas!B:B))=TRIM(TO_TEXT(D14)), Reservas!E:E<=$B$1, Reservas!F:F>$B$1 ), 1 ), """")"),"") | G14: =IFERROR(__xludf.DUMMYFUNCTION("IFERROR( INDEX( FILTER( Reservas!E:E, TRIM(TO_TEXT(Reservas!B:B))=TRIM(TO_TEXT(D14)), Reservas!E:E<=$B$1, Reservas!F:F>$B$1 ), 1 ), """")"),"") | H14: =IFERROR(__xludf.DUMMYFUNCTION("IFERROR( INDEX( FILTER( Reservas!F:F, TRIM(TO_TEXT(Reservas!B:B))=TRIM(TO_TEXT(D14)), Reservas!E:E<=$B$1, Reservas!F:F>$B$1 ), 1 ), """")"),"") | I14: =IFERROR(__xludf.DUMMYFUNCTION("IFERROR( INDEX( FILTER( Reservas!C:C&"" ""&Reservas!D:D, TRIM(TO_TEXT(Reservas!B:B))=TRIM(TO_TEXT(D14)), Reservas!E:E<=$B$1, Reservas!F:F>$B$1 ), 1 ), """")"),"")
E15: =IFERROR(__xludf.DUMMYFUNCTION("IF( IFERROR( ROWS( FILTER( Reservas!B:B, TO_TEXT(TRIM(Reservas!B:B)) = TO_TEXT(TRIM(D15)), Reservas!E:E <= $B$1, Reservas!F:F > $B$1 ) ),0 )>0, ""OCUPADA"", ""LIBRE"" )"),"LIBRE") -> LIBRE | F15: =IFERROR(__xludf.DUMMYFUNCTION("IFERROR( INDEX( FILTER( Reservas!G:G, TRIM(TO_TEXT(Reservas!B:B))=TRIM(TO_TEXT(D15)), Reservas!E:E<=$B$1, Reservas!F:F>$B$1 ), 1 ), """")"),"") | G15: =IFERROR(__xludf.DUMMYFUNCTION("IFERROR( INDEX( FILTER( Reservas!E:E, TRIM(TO_TEXT(Reservas!B:B))=TRIM(TO_TEXT(D15)), Reservas!E:E<=$B$1, Reservas!F:F>$B$1 ), 1 ), """")"),"") | H15: =IFERROR(__xludf.DUMMYFUNCTION("IFERROR( INDEX( FILTER( Reservas!F:F, TRIM(TO_TEXT(Reservas!B:B))=TRIM(TO_TEXT(D15)), Reservas!E:E<=$B$1, Reservas!F:F>$B$1 ), 1 ), """")"),"") | I15: =IFERROR(__xludf.DUMMYFUNCTION("IFERROR( INDEX( FILTER( Reservas!C:C&"" ""&Reservas!D:D, TRIM(TO_TEXT(Reservas!B:B))=TRIM(TO_TEXT(D15)), Reservas!E:E<=$B$1, Reservas!F:F>$B$1 ), 1 ), """")"),"")
E16: =IFERROR(__xludf.DUMMYFUNCTION("IF( IFERROR( ROWS( FILTER( Reservas!B:B, TO_TEXT(TRIM(Reservas!B:B)) = TO_TEXT(TRIM(D16)), Reservas!E:E <= $B$1, Reservas!F:F > $B$1 ) ),0 )>0, ""OCUPADA"", ""LIBRE"" )"),"LIBRE") -> LIBRE | F16: =IFERROR(__xludf.DUMMYFUNCTION("IFERROR( INDEX( FILTER( Reservas!G:G, TRIM(TO_TEXT(Reservas!B:B))=TRIM(TO_TEXT(D16)), Reservas!E:E<=$B$1, Reservas!F:F>$B$1 ), 1 ), """")"),"") | G16: =IFERROR(__xludf.DUMMYFUNCTION("IFERROR( INDEX( FILTER( Reservas!E:E, TRIM(TO_TEXT(Reservas!B:B))=TRIM(TO_TEXT(D16)), Reservas!E:E<=$B$1, Reservas!F:F>$B$1 ), 1 ), """")"),"") | H16: =IFERROR(__xludf.DUMMYFUNCTION("IFERROR( INDEX( FILTER( Reservas!F:F, TRIM(TO_TEXT(Reservas!B:B))=TRIM(TO_TEXT(D16)), Reservas!E:E<=$B$1, Reservas!F:F>$B$1 ), 1 ), """")"),"") | I16: =IFERROR(__xludf.DUMMYFUNCTION("IFERROR( INDEX( FILTER( Reservas!C:C&"" ""&Reservas!D:D, TRIM(TO_TEXT(Reservas!B:B))=TRIM(TO_TEXT(D16)), Reservas!E:E<=$B$1, Reservas!F:F>$B$1 ), 1 ), """")"),"")
E17: =IFERROR(__xludf.DUMMYFUNCTION("IF( IFERROR( ROWS( FILTER( Reservas!B:B, TO_TEXT(TRIM(Reservas!B:B)) = TO_TEXT(TRIM(D17)), Reservas!E:E <= $B$1, Reservas!F:F > $B$1 ) ),0 )>0, ""OCUPADA"", ""LIBRE"" )"),"LIBRE") -> LIBRE | F17: =IFERROR(__xludf.DUMMYFUNCTION("IFERROR( INDEX( FILTER( Reservas!G:G, TRIM(TO_TEXT(Reservas!B:B))=TRIM(TO_TEXT(D17)), Reservas!E:E<=$B$1, Reservas!F:F>$B$1 ), 1 ), """")"),"") | G17: =IFERROR(__xludf.DUMMYFUNCTION("IFERROR( INDEX( FILTER( Reservas!E:E, TRIM(TO_TEXT(Reservas!B:B))=TRIM(TO_TEXT(D17)), Reservas!E:E<=$B$1, Reservas!F:F>$B$1 ), 1 ), """")"),"") | H17: =IFERROR(__xludf.DUMMYFUNCTION("IFERROR( INDEX( FILTER( Reservas!F:F, TRIM(TO_TEXT(Reservas!B:B))=TRIM(TO_TEXT(D17)), Reservas!E:E<=$B$1, Reservas!F:F>$B$1 ), 1 ), """")"),"") | I17: =IFERROR(__xludf.DUMMYFUNCTION("IFERROR( INDEX( FILTER( Reservas!C:C&"" ""&Reservas!D:D, TRIM(TO_TEXT(Reservas!B:B))=TRIM(TO_TEXT(D17)), Reservas!E:E<=$B$1, Reservas!F:F>$B$1 ), 1 ), """")"),"")
E18: =IFERROR(__xludf.DUMMYFUNCTION("IF( IFERROR( ROWS( FILTER( Reservas!B:B, TO_TEXT(TRIM(Reservas!B:B)) = TO_TEXT(TRIM(D18)), Reservas!E:E <= $B$1, Reservas!F:F > $B$1 ) ),0 )>0, ""OCUPADA"", ""LIBRE"" )"),"LIBRE") -> LIBRE | F18: =IFERROR(__xludf.DUMMYFUNCTION("IFERROR( INDEX( FILTER( Reservas!G:G, TRIM(TO_TEXT(Reservas!B:B))=TRIM(TO_TEXT(D18)), Reservas!E:E<=$B$1, Reservas!F:F>$B$1 ), 1 ), """")"),"") | G18: =IFERROR(__xludf.DUMMYFUNCTION("IFERROR( INDEX( FILTER( Reservas!E:E, TRIM(TO_TEXT(Reservas!B:B))=TRIM(TO_TEXT(D18)), Reservas!E:E<=$B$1, Reservas!F:F>$B$1 ), 1 ), """")"),"") | H18: =IFERROR(__xludf.DUMMYFUNCTION("IFERROR( INDEX( FILTER( Reservas!F:F, TRIM(TO_TEXT(Reservas!B:B))=TRIM(TO_TEXT(D18)), Reservas!E:E<=$B$1, Reservas!F:F>$B$1 ), 1 ), """")"),"") | I18: =IFERROR(__xludf.DUMMYFUNCTION("IFERROR( INDEX( FILTER( Reservas!C:C&"" ""&Reservas!D:D, TRIM(TO_TEXT(Reservas!B:B))=TRIM(TO_TEXT(D18)), Reservas!E:E<=$B$1, Reservas!F:F>$B$1 ), 1 ), """")"),"")
E19: =IFERROR(__xludf.DUMMYFUNCTION("IF( IFERROR( ROWS( FILTER( Reservas!B:B, TO_TEXT(TRIM(Reservas!B:B)) = TO_TEXT(TRIM(D19)), Reservas!E:E <= $B$1, Reservas!F:F > $B$1 ) ),0 )>0, ""OCUPADA"", ""LIBRE"" )"),"LIBRE") -> LIBRE | F19: =IFERROR(__xludf.DUMMYFUNCTION("IFERROR( INDEX( FILTER( Reservas!G:G, TRIM(TO_TEXT(Reservas!B:B))=TRIM(TO_TEXT(D19)), Reservas!E:E<=$B$1, Reservas!F:F>$B$1 ), 1 ), """")"),"") | G19: =IFERROR(__xludf.DUMMYFUNCTION("IFERROR( INDEX( FILTER( Reservas!E:E, TRIM(TO_TEXT(Reservas!B:B))=TRIM(TO_TEXT(D19)), Reservas!E:E<=$B$1, Reservas!F:F>$B$1 ), 1 ), """")"),"") | H19: =IFERROR(__xludf.DUMMYFUNCTION("IFERROR( INDEX( FILTER( Reservas!F:F, TRIM(TO_TEXT(Reservas!B:B))=TRIM(TO_TEXT(D19)), Reservas!E:E<=$B$1, Reservas!F:F>$B$1 ), 1 ), """")"),"") | I19: =IFERROR(__xludf.DUMMYFUNCTION("IFERROR( INDEX( FILTER( Reservas!C:C&"" ""&Reservas!D:D, TRIM(TO_TEXT(Reservas!B:B))=TRIM(TO_TEXT(D19)), Reservas!E:E<=$B$1, Reservas!F:F>$B$1 ), 1 ), """")"),"")
E20: =IFERROR(__xludf.DUMMYFUNCTION("IF( IFERROR( ROWS( FILTER( Reservas!B:B, TO_TEXT(TRIM(Reservas!B:B)) = TO_TEXT(TRIM(D20)), Reservas!E:E <= $B$1, Reservas!F:F > $B$1 ) ),0 )>0, ""OCUPADA"", ""LIBRE"" )"),"LIBRE") -> LIBRE | F20: =IFERROR(__xludf.DUMMYFUNCTION("IFERROR( INDEX( FILTER( Reservas!G:G, TRIM(TO_TEXT(Reservas!B:B))=TRIM(TO_TEXT(D20)), Reservas!E:E<=$B$1, Reservas!F:F>$B$1 ), 1 ), """")"),"") | G20: =IFERROR(__xludf.DUMMYFUNCTION("IFERROR( INDEX( FILTER( Reservas!E:E, TRIM(TO_TEXT(Reservas!B:B))=TRIM(TO_TEXT(D20)), Reservas!E:E<=$B$1, Reservas!F:F>$B$1 ), 1 ), """")"),"") | H20: =IFERROR(__xludf.DUMMYFUNCTION("IFERROR( INDEX( FILTER( Reservas!F:F, TRIM(TO_TEXT(Reservas!B:B))=TRIM(TO_TEXT(D20)), Reservas!E:E<=$B$1, Reservas!F:F>$B$1 ), 1 ), """")"),"") | I20: =IFERROR(__xludf.DUMMYFUNCTION("IFERROR( INDEX( FILTER( Reservas!C:C&"" ""&Reservas!D:D, TRIM(TO_TEXT(Reservas!B:B))=TRIM(TO_TEXT(D20)), Reservas!E:E<=$B$1, Reservas!F:F>$B$1 ), 1 ), """")"),"")
E21: =IFERROR(__xludf.DUMMYFUNCTION("IF( IFERROR( ROWS( FILTER( Reservas!B:B, TO_TEXT(TRIM(Reservas!B:B)) = TO_TEXT(TRIM(D21)), Reservas!E:E <= $B$1, Reservas!F:F > $B$1 ) ),0 )>0, ""OCUPADA"", ""LIBRE"" )"),"LIBRE") -> LIBRE | F21: =IFERROR(__xludf.DUMMYFUNCTION("IFERROR( INDEX( FILTER( Reservas!G:G, TRIM(TO_TEXT(Reservas!B:B))=TRIM(TO_TEXT(D21)), Reservas!E:E<=$B$1, Reservas!F:F>$B$1 ), 1 ), """")"),"") | G21: =IFERROR(__xludf.DUMMYFUNCTION("IFERROR( INDEX( FILTER( Reservas!E:E, TRIM(TO_TEXT(Reservas!B:B))=TRIM(TO_TEXT(D21)), Reservas!E:E<=$B$1, Reservas!F:F>$B$1 ), 1 ), """")"),"") | H21: =IFERROR(__xludf.DUMMYFUNCTION("IFERROR( INDEX( FILTER( Reservas!F:F, TRIM(TO_TEXT(Reservas!B:B))=TRIM(TO_TEXT(D21)), Reservas!E:E<=$B$1, Reservas!F:F>$B$1 ), 1 ), """")"),"") | I21: =IFERROR(__xludf.DUMMYFUNCTION("IFERROR( INDEX( FILTER( Reservas!C:C&"" ""&Reservas!D:D, TRIM(TO_TEXT(Reservas!B:B))=TRIM(TO_TEXT(D21)), Reservas!E:E<=$B$1, Reservas!F:F>$B$1 ), 1 ), """")"),"")
E22: =IFERROR(__xludf.DUMMYFUNCTION("IF( IFERROR( ROWS( FILTER( Reservas!B:B, TO_TEXT(TRIM(Reservas!B:B)) = TO_TEXT(TRIM(D22)), Reservas!E:E <= $B$1, Reservas!F:F > $B$1 ) ),0 )>0, ""OCUPADA"", ""LIBRE"" )"),"LIBRE") -> LIBRE | F22: =IFERROR(__xludf.DUMMYFUNCTION("IFERROR( INDEX( FILTER( Reservas!G:G, TRIM(TO_TEXT(Reservas!B:B))=TRIM(TO_TEXT(D22)), Reservas!E:E<=$B$1, Reservas!F:F>$B$1 ), 1 ), """")"),"") | G22: =IFERROR(__xludf.DUMMYFUNCTION("IFERROR( INDEX( FILTER( Reservas!E:E, TRIM(TO_TEXT(Reservas!B:B))=TRIM(TO_TEXT(D22)), Reservas!E:E<=$B$1, Reservas!F:F>$B$1 ), 1 ), """")"),"") | H22: =IFERROR(__xludf.DUMMYFUNCTION("IFERROR( INDEX( FILTER( Reservas!F:F, TRIM(TO_TEXT(Reservas!B:B))=TRIM(TO_TEXT(D22)), Reservas!E:E<=$B$1, Reservas!F:F>$B$1 ), 1 ), """")"),"") | I22: =IFERROR(__xludf.DUMMYFUNCTION("IFERROR( INDEX( FILTER( Reservas!C:C&"" ""&Reservas!D:D, TRIM(TO_TEXT(Reservas!B:B))=TRIM(TO_TEXT(D22)), Reservas!E:E<=$B$1, Reservas!F:F>$B$1 ), 1 ), """")"),"")
E23: =IFERROR(__xludf.DUMMYFUNCTION("IF( IFERROR( ROWS( FILTER( Reservas!B:B, TO_TEXT(TRIM(Reservas!B:B)) = TO_TEXT(TRIM(D23)), Reservas!E:E <= $B$1, Reservas!F:F > $B$1 ) ),0 )>0, ""OCUPADA"", ""LIBRE"" )"),"LIBRE") -> LIBRE | F23: =IFERROR(__xludf.DUMMYFUNCTION("IFERROR( INDEX( FILTER( Reservas!G:G, TRIM(TO_TEXT(Reservas!B:B))=TRIM(TO_TEXT(D23)), Reservas!E:E<=$B$1, Reservas!F:F>$B$1 ), 1 ), """")"),"") | G23: =IFERROR(__xludf.DUMMYFUNCTION("IFERROR( INDEX( FILTER( Reservas!E:E, TRIM(TO_TEXT(Reservas!B:B))=TRIM(TO_TEXT(D23)), Reservas!E:E<=$B$1, Reservas!F:F>$B$1 ), 1 ), """")"),"") | H23: =IFERROR(__xludf.DUMMYFUNCTION("IFERROR( INDEX( FILTER( Reservas!F:F, TRIM(TO_TEXT(Reservas!B:B))=TRIM(TO_TEXT(D23)), Reservas!E:E<=$B$1, Reservas!F:F>$B$1 ), 1 ), """")"),"") | I23: =IFERROR(__xludf.DUMMYFUNCTION("IFERROR( INDEX( FILTER( Reservas!C:C&"" ""&Reservas!D:D, TRIM(TO_TEXT(Reservas!B:B))=TRIM(TO_TEXT(D23)), Reservas!E:E<=$B$1, Reservas!F:F>$B$1 ), 1 ), """")"),"")
E24: =IFERROR(__xludf.DUMMYFUNCTION("IF( IFERROR( ROWS( FILTER( Reservas!B:B, TO_TEXT(TRIM(Reservas!B:B)) = TO_TEXT(TRIM(D24)), Reservas!E:E <= $B$1, Reservas!F:F > $B$1 ) ),0 )>0, ""OCUPADA"", ""LIBRE"" )"),"LIBRE") -> LIBRE | F24: =IFERROR(__xludf.DUMMYFUNCTION("IFERROR( INDEX( FILTER( Reservas!G:G, TRIM(TO_TEXT(Reservas!B:B))=TRIM(TO_TEXT(D24)), Reservas!E:E<=$B$1, Reservas!F:F>$B$1 ), 1 ), """")"),"") | G24: =IFERROR(__xludf.DUMMYFUNCTION("IFERROR( INDEX( FILTER( Reservas!E:E, TRIM(TO_TEXT(Reservas!B:B))=TRIM(TO_TEXT(D24)), Reservas!E:E<=$B$1, Reservas!F:F>$B$1 ), 1 ), """")"),"") | H24: =IFERROR(__xludf.DUMMYFUNCTION("IFERROR( INDEX( FILTER( Reservas!F:F, TRIM(TO_TEXT(Reservas!B:B))=TRIM(TO_TEXT(D24)), Reservas!E:E<=$B$1, Reservas!F:F>$B$1 ), 1 ), """")"),"") | I24: =IFERROR(__xludf.DUMMYFUNCTION("IFERROR( INDEX( FILTER( Reservas!C:C&"" ""&Reservas!D:D, TRIM(TO_TEXT(Reservas!B:B))=TRIM(TO_TEXT(D24)), Reservas!E:E<=$B$1, Reservas!F:F>$B$1 ), 1 ), """")"),"")
E25: =IFERROR(__xludf.DUMMYFUNCTION("IF( IFERROR( ROWS( FILTER( Reservas!B:B, TO_TEXT(TRIM(Reservas!B:B)) = TO_TEXT(TRIM(D25)), Reservas!E:E <= $B$1, Reservas!F:F > $B$1 ) ),0 )>0, ""OCUPADA"", ""LIBRE"" )"),"LIBRE") -> LIBRE | F25: =IFERROR(__xludf.DUMMYFUNCTION("IFERROR( INDEX( FILTER( Reservas!G:G, TRIM(TO_TEXT(Reservas!B:B))=TRIM(TO_TEXT(D25)), Reservas!E:E<=$B$1, Reservas!F:F>$B$1 ), 1 ), """")"),"") | G25: =IFERROR(__xludf.DUMMYFUNCTION("IFERROR( INDEX( FILTER( Reservas!E:E, TRIM(TO_TEXT(Reservas!B:B))=TRIM(TO_TEXT(D25)), Reservas!E:E<=$B$1, Reservas!F:F>$B$1 ), 1 ), """")"),"") | H25: =IFERROR(__xludf.DUMMYFUNCTION("IFERROR( INDEX( FILTER( Reservas!F:F, TRIM(TO_TEXT(Reservas!B:B))=TRIM(TO_TEXT(D25)), Reservas!E:E<=$B$1, Reservas!F:F>$B$1 ), 1 ), """")"),"") | I25: =IFERROR(__xludf.DUMMYFUNCTION("IFERROR( INDEX( FILTER( Reservas!C:C&"" ""&Reservas!D:D, TRIM(TO_TEXT(Reservas!B:B))=TRIM(TO_TEXT(D25)), Reservas!E:E<=$B$1, Reservas!F:F>$B$1 ), 1 ), """")"),"")
E26: =IFERROR(__xludf.DUMMYFUNCTION("IF( IFERROR( ROWS( FILTER( Reservas!B:B, TO_TEXT(TRIM(Reservas!B:B)) = TO_TEXT(TRIM(D26)), Reservas!E:E <= $B$1, Reservas!F:F > $B$1 ) ),0 )>0, ""OCUPADA"", ""LIBRE"" )"),"LIBRE") -> LIBRE | F26: =IFERROR(__xludf.DUMMYFUNCTION("IFERROR( INDEX( FILTER( Reservas!G:G, TRIM(TO_TEXT(Reservas!B:B))=TRIM(TO_TEXT(D26)), Reservas!E:E<=$B$1, Reservas!F:F>$B$1 ), 1 ), """")"),"") | G26: =IFERROR(__xludf.DUMMYFUNCTION("IFERROR( INDEX( FILTER( Reservas!E:E, TRIM(TO_TEXT(Reservas!B:B))=TRIM(TO_TEXT(D26)), Reservas!E:E<=$B$1, Reservas!F:F>$B$1 ), 1 ), """")"),"") | H26: =IFERROR(__xludf.DUMMYFUNCTION("IFERROR( INDEX( FILTER( Reservas!F:F, TRIM(TO_TEXT(Reservas!B:B))=TRIM(TO_TEXT(D26)), Reservas!E:E<=$B$1, Reservas!F:F>$B$1 ), 1 ), """")"),"") | I26: =IFERROR(__xludf.DUMMYFUNCTION("IFERROR( INDEX( FILTER( Reservas!C:C&"" ""&Reservas!D:D, TRIM(TO_TEXT(Reservas!B:B))=TRIM(TO_TEXT(D26)), Reservas!E:E<=$B$1, Reservas!F:F>$B$1 ), 1 ), """")"),"")
E27: =IFERROR(__xludf.DUMMYFUNCTION("IF( IFERROR( ROWS( FILTER( Reservas!B:B, TO_TEXT(TRIM(Reservas!B:B)) = TO_TEXT(TRIM(D27)), Reservas!E:E <= $B$1, Reservas!F:F > $B$1 ) ),0 )>0, ""OCUPADA"", ""LIBRE"" )"),"LIBRE") -> LIBRE | F27: =IFERROR(__xludf.DUMMYFUNCTION("IFERROR( INDEX( FILTER( Reservas!G:G, TRIM(TO_TEXT(Reservas!B:B))=TRIM(TO_TEXT(D27)), Reservas!E:E<=$B$1, Reservas!F:F>$B$1 ), 1 ), """")"),"") | G27: =IFERROR(__xludf.DUMMYFUNCTION("IFERROR( INDEX( FILTER( Reservas!E:E, TRIM(TO_TEXT(Reservas!B:B))=TRIM(TO_TEXT(D27)), Reservas!E:E<=$B$1, Reservas!F:F>$B$1 ), 1 ), """")"),"") | H27: =IFERROR(__xludf.DUMMYFUNCTION("IFERROR( INDEX( FILTER( Reservas!F:F, TRIM(TO_TEXT(Reservas!B:B))=TRIM(TO_TEXT(D27)), Reservas!E:E<=$B$1, Reservas!F:F>$B$1 ), 1 ), """")"),"") | I27: =IFERROR(__xludf.DUMMYFUNCTION("IFERROR( INDEX( FILTER( Reservas!C:C&"" ""&Reservas!D:D, TRIM(TO_TEXT(Reservas!B:B))=TRIM(TO_TEXT(D27)), Reservas!E:E<=$B$1, Reservas!F:F>$B$1 ), 1 ), """")"),"")
E28: =IFERROR(__xludf.DUMMYFUNCTION("IF( IFERROR( ROWS( FILTER( Reservas!B:B, TO_TEXT(TRIM(Reservas!B:B)) = TO_TEXT(TRIM(D28)), Reservas!E:E <= $B$1, Reservas!F:F > $B$1 ) ),0 )>0, ""OCUPADA"", ""LIBRE"" )"),"LIBRE") -> LIBRE | F28: =IFERROR(__xludf.DUMMYFUNCTION("IFERROR( INDEX( FILTER( Reservas!G:G, TRIM(TO_TEXT(Reservas!B:B))=TRIM(TO_TEXT(D28)), Reservas!E:E<=$B$1, Reservas!F:F>$B$1 ), 1 ), """")"),"") | G28: =IFERROR(__xludf.DUMMYFUNCTION("IFERROR( INDEX( FILTER( Reservas!E:E, TRIM(TO_TEXT(Reservas!B:B))=TRIM(TO_TEXT(D28)), Reservas!E:E<=$B$1, Reservas!F:F>$B$1 ), 1 ), """")"),"") | H28: =IFERROR(__xludf.DUMMYFUNCTION("IFERROR( INDEX( FILTER( Reservas!F:F, TRIM(TO_TEXT(Reservas!B:B))=TRIM(TO_TEXT(D28)), Reservas!E:E<=$B$1, Reservas!F:F>$B$1 ), 1 ), """")"),"") | I28: =IFERROR(__xludf.DUMMYFUNCTION("IFERROR( INDEX( FILTER( Reservas!C:C&"" ""&Reservas!D:D, TRIM(TO_TEXT(Reservas!B:B))=TRIM(TO_TEXT(D28)), Reservas!E:E<=$B$1, Reservas!F:F>$B$1 ), 1 ), """")"),"")
E29: =IFERROR(__xludf.DUMMYFUNCTION("IF( IFERROR( ROWS( FILTER( Reservas!B:B, TO_TEXT(TRIM(Reservas!B:B)) = TO_TEXT(TRIM(D29)), Reservas!E:E <= $B$1, Reservas!F:F > $B$1 ) ),0 )>0, ""OCUPADA"", ""LIBRE"" )"),"LIBRE") -> LIBRE | F29: =IFERROR(__xludf.DUMMYFUNCTION("IFERROR( INDEX( FILTER( Reservas!G:G, TRIM(TO_TEXT(Reservas!B:B))=TRIM(TO_TEXT(D29)), Reservas!E:E<=$B$1, Reservas!F:F>$B$1 ), 1 ), """")"),"") | G29: =IFERROR(__xludf.DUMMYFUNCTION("IFERROR( INDEX( FILTER( Reservas!E:E, TRIM(TO_TEXT(Reservas!B:B))=TRIM(TO_TEXT(D29)), Reservas!E:E<=$B$1, Reservas!F:F>$B$1 ), 1 ), """")"),"") | H29: =IFERROR(__xludf.DUMMYFUNCTION("IFERROR( INDEX( FILTER( Reservas!F:F, TRIM(TO_TEXT(Reservas!B:B))=TRIM(TO_TEXT(D29)), Reservas!E:E<=$B$1, Reservas!F:F>$B$1 ), 1 ), """")"),"") | I29: =IFERROR(__xludf.DUMMYFUNCTION("IFERROR( INDEX( FILTER( Reservas!C:C&"" ""&Reservas!D:D, TRIM(TO_TEXT(Reservas!B:B))=TRIM(TO_TEXT(D29)), Reservas!E:E<=$B$1, Reservas!F:F>$B$1 ), 1 ), """")"),"")
E30: =IFERROR(__xludf.DUMMYFUNCTION("IF( IFERROR( ROWS( FILTER( Reservas!B:B, TO_TEXT(TRIM(Reservas!B:B)) = TO_TEXT(TRIM(D30)), Reservas!E:E <= $B$1, Reservas!F:F > $B$1 ) ),0 )>0, ""OCUPADA"", ""LIBRE"" )"),"LIBRE") -> LIBRE | F30: =IFERROR(__xludf.DUMMYFUNCTION("IFERROR( INDEX( FILTER( Reservas!G:G, TRIM(TO_TEXT(Reservas!B:B))=TRIM(TO_TEXT(D30)), Reservas!E:E<=$B$1, Reservas!F:F>$B$1 ), 1 ), """")"),"") | G30: =IFERROR(__xludf.DUMMYFUNCTION("IFERROR( INDEX( FILTER( Reservas!E:E, TRIM(TO_TEXT(Reservas!B:B))=TRIM(TO_TEXT(D30)), Reservas!E:E<=$B$1, Reservas!F:F>$B$1 ), 1 ), """")"),"") | H30: =IFERROR(__xludf.DUMMYFUNCTION("IFERROR( INDEX( FILTER( Reservas!F:F, TRIM(TO_TEXT(Reservas!B:B))=TRIM(TO_TEXT(D30)), Reservas!E:E<=$B$1, Reservas!F:F>$B$1 ), 1 ), """")"),"") | I30: =IFERROR(__xludf.DUMMYFUNCTION("IFERROR( INDEX( FILTER( Reservas!C:C&"" ""&Reservas!D:D, TRIM(TO_TEXT(Reservas!B:B))=TRIM(TO_TEXT(D30)), Reservas!E:E<=$B$1, Reservas!F:F>$B$1 ), 1 ), """")"),"")
E31: =IFERROR(__xludf.DUMMYFUNCTION("IF( IFERROR( ROWS( FILTER( Reservas!B:B, TO_TEXT(TRIM(Reservas!B:B)) = TO_TEXT(TRIM(D31)), Reservas!E:E <= $B$1, Reservas!F:F > $B$1 ) ),0 )>0, ""OCUPADA"", ""LIBRE"" )"),"LIBRE") -> LIBRE | F31: =IFERROR(__xludf.DUMMYFUNCTION("IFERROR( INDEX( FILTER( Reservas!G:G, TRIM(TO_TEXT(Reservas!B:B))=TRIM(TO_TEXT(D31)), Reservas!E:E<=$B$1, Reservas!F:F>$B$1 ), 1 ), """")"),"") | G31: =IFERROR(__xludf.DUMMYFUNCTION("IFERROR( INDEX( FILTER( Reservas!E:E, TRIM(TO_TEXT(Reservas!B:B))=TRIM(TO_TEXT(D31)), Reservas!E:E<=$B$1, Reservas!F:F>$B$1 ), 1 ), """")"),"") | H31: =IFERROR(__xludf.DUMMYFUNCTION("IFERROR( INDEX( FILTER( Reservas!F:F, TRIM(TO_TEXT(Reservas!B:B))=TRIM(TO_TEXT(D31)), Reservas!E:E<=$B$1, Reservas!F:F>$B$1 ), 1 ), """")"),"") | I31: =IFERROR(__xludf.DUMMYFUNCTION("IFERROR( INDEX( FILTER( Reservas!C:C&"" ""&Reservas!D:D, TRIM(TO_TEXT(Reservas!B:B))=TRIM(TO_TEXT(D31)), Reservas!E:E<=$B$1, Reservas!F:F>$B$1 ), 1 ), """")"),"")
E32: =IFERROR(__xludf.DUMMYFUNCTION("IF( IFERROR( ROWS( FILTER( Reservas!B:B, TO_TEXT(TRIM(Reservas!B:B)) = TO_TEXT(TRIM(D32)), Reservas!E:E <= $B$1, Reservas!F:F > $B$1 ) ),0 )>0, ""OCUPADA"", ""LIBRE"" )"),"LIBRE") -> LIBRE | F32: =IFERROR(__xludf.DUMMYFUNCTION("IFERROR( INDEX( FILTER( Reservas!G:G, TRIM(TO_TEXT(Reservas!B:B))=TRIM(TO_TEXT(D32)), Reservas!E:E<=$B$1, Reservas!F:F>$B$1 ), 1 ), """")"),"") | G32: =IFERROR(__xludf.DUMMYFUNCTION("IFERROR( INDEX( FILTER( Reservas!E:E, TRIM(TO_TEXT(Reservas!B:B))=TRIM(TO_TEXT(D32)), Reservas!E:E<=$B$1, Reservas!F:F>$B$1 ), 1 ), """")"),"") | H32: =IFERROR(__xludf.DUMMYFUNCTION("IFERROR( INDEX( FILTER( Reservas!F:F, TRIM(TO_TEXT(Reservas!B:B))=TRIM(TO_TEXT(D32)), Reservas!E:E<=$B$1, Reservas!F:F>$B$1 ), 1 ), """")"),"") | I32: =IFERROR(__xludf.DUMMYFUNCTION("IFERROR( INDEX( FILTER( Reservas!C:C&"" ""&Reservas!D:D, TRIM(TO_TEXT(Reservas!B:B))=TRIM(TO_TEXT(D32)), Reservas!E:E<=$B$1, Reservas!F:F>$B$1 ), 1 ), """")"),"")
E33: =IFERROR(__xludf.DUMMYFUNCTION("IF( IFERROR( ROWS( FILTER( Reservas!B:B, TO_TEXT(TRIM(Reservas!B:B)) = TO_TEXT(TRIM(D33)), Reservas!E:E <= $B$1, Reservas!F:F > $B$1 ) ),0 )>0, ""OCUPADA"", ""LIBRE"" )"),"LIBRE") -> LIBRE | F33: =IFERROR(__xludf.DUMMYFUNCTION("IFERROR( INDEX( FILTER( Reservas!G:G, TRIM(TO_TEXT(Reservas!B:B))=TRIM(TO_TEXT(D33)), Reservas!E:E<=$B$1, Reservas!F:F>$B$1 ), 1 ), """")"),"") | G33: =IFERROR(__xludf.DUMMYFUNCTION("IFERROR( INDEX( FILTER( Reservas!E:E, TRIM(TO_TEXT(Reservas!B:B))=TRIM(TO_TEXT(D33)), Reservas!E:E<=$B$1, Reservas!F:F>$B$1 ), 1 ), """")"),"") | H33: =IFERROR(__xludf.DUMMYFUNCTION("IFERROR( INDEX( FILTER( Reservas!F:F, TRIM(TO_TEXT(Reservas!B:B))=TRIM(TO_TEXT(D33)), Reservas!E:E<=$B$1, Reservas!F:F>$B$1 ), 1 ), """")"),"") | I33: =IFERROR(__xludf.DUMMYFUNCTION("IFERROR( INDEX( FILTER( Reservas!C:C&"" ""&Reservas!D:D, TRIM(TO_TEXT(Reservas!B:B))=TRIM(TO_TEXT(D33)), Reservas!E:E<=$B$1, Reservas!F:F>$B$1 ), 1 ), """")"),"")
E34: =IFERROR(__xludf.DUMMYFUNCTION("IF( IFERROR( ROWS( FILTER( Reservas!B:B, TO_TEXT(TRIM(Reservas!B:B)) = TO_TEXT(TRIM(D34)), Reservas!E:E <= $B$1, Reservas!F:F > $B$1 ) ),0 )>0, ""OCUPADA"", ""LIBRE"" )"),"LIBRE") -> LIBRE | F34: =IFERROR(__xludf.DUMMYFUNCTION("IFERROR( INDEX( FILTER( Reservas!G:G, TRIM(TO_TEXT(Reservas!B:B))=TRIM(TO_TEXT(D34)), Reservas!E:E<=$B$1, Reservas!F:F>$B$1 ), 1 ), """")"),"") | G34: =IFERROR(__xludf.DUMMYFUNCTION("IFERROR( INDEX( FILTER( Reservas!E:E, TRIM(TO_TEXT(Reservas!B:B))=TRIM(TO_TEXT(D34)), Reservas!E:E<=$B$1, Reservas!F:F>$B$1 ), 1 ), """")"),"") | H34: =IFERROR(__xludf.DUMMYFUNCTION("IFERROR( INDEX( FILTER( Reservas!F:F, TRIM(TO_TEXT(Reservas!B:B))=TRIM(TO_TEXT(D34)), Reservas!E:E<=$B$1, Reservas!F:F>$B$1 ), 1 ), """")"),"") | I34: =IFERROR(__xludf.DUMMYFUNCTION("IFERROR( INDEX( FILTER( Reservas!C:C&"" ""&Reservas!D:D, TRIM(TO_TEXT(Reservas!B:B))=TRIM(TO_TEXT(D34)), Reservas!E:E<=$B$1, Reservas!F:F>$B$1 ), 1 ), """")"),"")
E35: =IFERROR(__xludf.DUMMYFUNCTION("IF( IFERROR( ROWS( FILTER( Reservas!B:B, TO_TEXT(TRIM(Reservas!B:B)) = TO_TEXT(TRIM(D35)), Reservas!E:E <= $B$1, Reservas!F:F > $B$1 ) ),0 )>0, ""OCUPADA"", ""LIBRE"" )"),"LIBRE") -> LIBRE | F35: =IFERROR(__xludf.DUMMYFUNCTION("IFERROR( INDEX( FILTER( Reservas!G:G, TRIM(TO_TEXT(Reservas!B:B))=TRIM(TO_TEXT(D35)), Reservas!E:E<=$B$1, Reservas!F:F>$B$1 ), 1 ), """")"),"") | G35: =IFERROR(__xludf.DUMMYFUNCTION("IFERROR( INDEX( FILTER( Reservas!E:E, TRIM(TO_TEXT(Reservas!B:B))=TRIM(TO_TEXT(D35)), Reservas!E:E<=$B$1, Reservas!F:F>$B$1 ), 1 ), """")"),"") | H35: =IFERROR(__xludf.DUMMYFUNCTION("IFERROR( INDEX( FILTER( Reservas!F:F, TRIM(TO_TEXT(Reservas!B:B))=TRIM(TO_TEXT(D35)), Reservas!E:E<=$B$1, Reservas!F:F>$B$1 ), 1 ), """")"),"") | I35: =IFERROR(__xludf.DUMMYFUNCTION("IFERROR( INDEX( FILTER( Reservas!C:C&"" ""&Reservas!D:D, TRIM(TO_TEXT(Reservas!B:B))=TRIM(TO_TEXT(D35)), Reservas!E:E<=$B$1, Reservas!F:F>$B$1 ), 1 ), """")"),"")
E36: =IFERROR(__xludf.DUMMYFUNCTION("IF( IFERROR( ROWS( FILTER( Reservas!B:B, TO_TEXT(TRIM(Reservas!B:B)) = TO_TEXT(TRIM(D36)), Reservas!E:E <= $B$1, Reservas!F:F > $B$1 ) ),0 )>0, ""OCUPADA"", ""LIBRE"" )"),"LIBRE") -> LIBRE | F36: =IFERROR(__xludf.DUMMYFUNCTION("IFERROR( INDEX( FILTER( Reservas!G:G, TRIM(TO_TEXT(Reservas!B:B))=TRIM(TO_TEXT(D36)), Reservas!E:E<=$B$1, Reservas!F:F>$B$1 ), 1 ), """")"),"") | G36: =IFERROR(__xludf.DUMMYFUNCTION("IFERROR( INDEX( FILTER( Reservas!E:E, TRIM(TO_TEXT(Reservas!B:B))=TRIM(TO_TEXT(D36)), Reservas!E:E<=$B$1, Reservas!F:F>$B$1 ), 1 ), """")"),"") | H36: =IFERROR(__xludf.DUMMYFUNCTION("IFERROR( INDEX( FILTER( Reservas!F:F, TRIM(TO_TEXT(Reservas!B:B))=TRIM(TO_TEXT(D36)), Reservas!E:E<=$B$1, Reservas!F:F>$B$1 ), 1 ), """")"),"") | I36: =IFERROR(__xludf.DUMMYFUNCTION("IFERROR( INDEX( FILTER( Reservas!C:C&"" ""&Reservas!D:D, TRIM(TO_TEXT(Reservas!B:B))=TRIM(TO_TEXT(D36)), Reservas!E:E<=$B$1, Reservas!F:F>$B$1 ), 1 ), """")"),"")
E37: =IFERROR(__xludf.DUMMYFUNCTION("IF( IFERROR( ROWS( FILTER( Reservas!B:B, TO_TEXT(TRIM(Reservas!B:B)) = TO_TEXT(TRIM(D37)), Reservas!E:E <= $B$1, Reservas!F:F > $B$1 ) ),0 )>0, ""OCUPADA"", ""LIBRE"" )"),"LIBRE") -> LIBRE | F37: =IFERROR(__xludf.DUMMYFUNCTION("IFERROR( INDEX( FILTER( Reservas!G:G, TRIM(TO_TEXT(Reservas!B:B))=TRIM(TO_TEXT(D37)), Reservas!E:E<=$B$1, Reservas!F:F>$B$1 ), 1 ), """")"),"") | G37: =IFERROR(__xludf.DUMMYFUNCTION("IFERROR( INDEX( FILTER( Reservas!E:E, TRIM(TO_TEXT(Reservas!B:B))=TRIM(TO_TEXT(D37)), Reservas!E:E<=$B$1, Reservas!F:F>$B$1 ), 1 ), """")"),"") | H37: =IFERROR(__xludf.DUMMYFUNCTION("IFERROR( INDEX( FILTER( Reservas!F:F, TRIM(TO_TEXT(Reservas!B:B))=TRIM(TO_TEXT(D37)), Reservas!E:E<=$B$1, Reservas!F:F>$B$1 ), 1 ), """")"),"") | I37: =IFERROR(__xludf.DUMMYFUNCTION("IFERROR( INDEX( FILTER( Reservas!C:C&"" ""&Reservas!D:D, TRIM(TO_TEXT(Reservas!B:B))=TRIM(TO_TEXT(D37)), Reservas!E:E<=$B$1, Reservas!F:F>$B$1 ), 1 ), """")"),"")
E38: =IFERROR(__xludf.DUMMYFUNCTION("IF( IFERROR( ROWS( FILTER( Reservas!B:B, TO_TEXT(TRIM(Reservas!B:B)) = TO_TEXT(TRIM(D38)), Reservas!E:E <= $B$1, Reservas!F:F > $B$1 ) ),0 )>0, ""OCUPADA"", ""LIBRE"" )"),"LIBRE") -> LIBRE | F38: =IFERROR(__xludf.DUMMYFUNCTION("IFERROR( INDEX( FILTER( Reservas!G:G, TRIM(TO_TEXT(Reservas!B:B))=TRIM(TO_TEXT(D38)), Reservas!E:E<=$B$1, Reservas!F:F>$B$1 ), 1 ), """")"),"") | G38: =IFERROR(__xludf.DUMMYFUNCTION("IFERROR( INDEX( FILTER( Reservas!E:E, TRIM(TO_TEXT(Reservas!B:B))=TRIM(TO_TEXT(D38)), Reservas!E:E<=$B$1, Reservas!F:F>$B$1 ), 1 ), """")"),"") | H38: =IFERROR(__xludf.DUMMYFUNCTION("IFERROR( INDEX( FILTER( Reservas!F:F, TRIM(TO_TEXT(Reservas!B:B))=TRIM(TO_TEXT(D38)), Reservas!E:E<=$B$1, Reservas!F:F>$B$1 ), 1 ), """")"),"") | I38: =IFERROR(__xludf.DUMMYFUNCTION("IFERROR( INDEX( FILTER( Reservas!C:C&"" ""&Reservas!D:D, TRIM(TO_TEXT(Reservas!B:B))=TRIM(TO_TEXT(D38)), Reservas!E:E<=$B$1, Reservas!F:F>$B$1 ), 1 ), """")"),"")
E39: =IFERROR(__xludf.DUMMYFUNCTION("IF( IFERROR( ROWS( FILTER( Reservas!B:B, TO_TEXT(TRIM(Reservas!B:B)) = TO_TEXT(TRIM(D39)), Reservas!E:E <= $B$1, Reservas!F:F > $B$1 ) ),0 )>0, ""OCUPADA"", ""LIBRE"" )"),"LIBRE") -> LIBRE | F39: =IFERROR(__xludf.DUMMYFUNCTION("IFERROR( INDEX( FILTER( Reservas!G:G, TRIM(TO_TEXT(Reservas!B:B))=TRIM(TO_TEXT(D39)), Reservas!E:E<=$B$1, Reservas!F:F>$B$1 ), 1 ), """")"),"") | G39: =IFERROR(__xludf.DUMMYFUNCTION("IFERROR( INDEX( FILTER( Reservas!E:E, TRIM(TO_TEXT(Reservas!B:B))=TRIM(TO_TEXT(D39)), Reservas!E:E<=$B$1, Reservas!F:F>$B$1 ), 1 ), """")"),"") | H39: =IFERROR(__xludf.DUMMYFUNCTION("IFERROR( INDEX( FILTER( Reservas!F:F, TRIM(TO_TEXT(Reservas!B:B))=TRIM(TO_TEXT(D39)), Reservas!E:E<=$B$1, Reservas!F:F>$B$1 ), 1 ), """")"),"") | I39: =IFERROR(__xludf.DUMMYFUNCTION("IFERROR( INDEX( FILTER( Reservas!C:C&"" ""&Reservas!D:D, TRIM(TO_TEXT(Reservas!B:B))=TRIM(TO_TEXT(D39)), Reservas!E:E<=$B$1, Reservas!F:F>$B$1 ), 1 ), """")"),"")
E40: =IFERROR(__xludf.DUMMYFUNCTION("IF( IFERROR( ROWS( FILTER( Reservas!B:B, TO_TEXT(TRIM(Reservas!B:B)) = TO_TEXT(TRIM(D40)), Reservas!E:E <= $B$1, Reservas!F:F > $B$1 ) ),0 )>0, ""OCUPADA"", ""LIBRE"" )"),"LIBRE") -> LIBRE | F40: =IFERROR(__xludf.DUMMYFUNCTION("IFERROR( INDEX( FILTER( Reservas!G:G, TRIM(TO_TEXT(Reservas!B:B))=TRIM(TO_TEXT(D40)), Reservas!E:E<=$B$1, Reservas!F:F>$B$1 ), 1 ), """")"),"") | G40: =IFERROR(__xludf.DUMMYFUNCTION("IFERROR( INDEX( FILTER( Reservas!E:E, TRIM(TO_TEXT(Reservas!B:B))=TRIM(TO_TEXT(D40)), Reservas!E:E<=$B$1, Reservas!F:F>$B$1 ), 1 ), """")"),"") | H40: =IFERROR(__xludf.DUMMYFUNCTION("IFERROR( INDEX( FILTER( Reservas!F:F, TRIM(TO_TEXT(Reservas!B:B))=TRIM(TO_TEXT(D40)), Reservas!E:E<=$B$1, Reservas!F:F>$B$1 ), 1 ), """")"),"") | I40: =IFERROR(__xludf.DUMMYFUNCTION("IFERROR( INDEX( FILTER( Reservas!C:C&"" ""&Reservas!D:D, TRIM(TO_TEXT(Reservas!B:B))=TRIM(TO_TEXT(D40)), Reservas!E:E<=$B$1, Reservas!F:F>$B$1 ), 1 ), """")"),"")
E41: =IFERROR(__xludf.DUMMYFUNCTION("IF( IFERROR( ROWS( FILTER( Reservas!B:B, TO_TEXT(TRIM(Reservas!B:B)) = TO_TEXT(TRIM(D41)), Reservas!E:E <= $B$1, Reservas!F:F > $B$1 ) ),0 )>0, ""OCUPADA"", ""LIBRE"" )"),"LIBRE") -> LIBRE | F41: =IFERROR(__xludf.DUMMYFUNCTION("IFERROR( INDEX( FILTER( Reservas!G:G, TRIM(TO_TEXT(Reservas!B:B))=TRIM(TO_TEXT(D41)), Reservas!E:E<=$B$1, Reservas!F:F>$B$1 ), 1 ), """")"),"") | G41: =IFERROR(__xludf.DUMMYFUNCTION("IFERROR( INDEX( FILTER( Reservas!E:E, TRIM(TO_TEXT(Reservas!B:B))=TRIM(TO_TEXT(D41)), Reservas!E:E<=$B$1, Reservas!F:F>$B$1 ), 1 ), """")"),"") | H41: =IFERROR(__xludf.DUMMYFUNCTION("IFERROR( INDEX( FILTER( Reservas!F:F, TRIM(TO_TEXT(Reservas!B:B))=TRIM(TO_TEXT(D41)), Reservas!E:E<=$B$1, Reservas!F:F>$B$1 ), 1 ), """")"),"") | I41: =IFERROR(__xludf.DUMMYFUNCTION("IFERROR( INDEX( FILTER( Reservas!C:C&"" ""&Reservas!D:D, TRIM(TO_TEXT(Reservas!B:B))=TRIM(TO_TEXT(D41)), Reservas!E:E<=$B$1, Reservas!F:F>$B$1 ), 1 ), """")"),"")
...

Sheet Lista de espera Via I
A1: Nombre y Apellido | B1: Fecha de reserva | C1: Fecha de solicitud | D1: Medio de contacto | E1: Observaciones | F1: Teléfono/mail
A2: Analia Grosso | B2: 23/1/27 al 31/1/27 inc. | D2: Whatsapp - mail | E2: Reservó Esq. De quedar libre, pasa al via. | G2: Avisados
A3: Natalia Roth | B3: 9/1/27 al 15/1/27 inc. | C3: 46294 | D3: Whatsapp | E3: Son dos familias. Quieren esq y via | F3: 341 3665374 | G3: Avisados
A4: Carolina Roth | B4: 9/1/27 al 15/1/27 inc. | C4: 46294 | D4: Whatsapp | E4: Son dos familias. Quieren esq y via | F4: 341 3565567 | G4: Avisados
A5: Catalina Sivit | B5: 2° quincena enero | C5: 46307 | D5: teléfono | E5: Son cinco personas. | F5: 3463 645630
